<?xml version="1.0" encoding="utf-8"?>
<robot name="digit">
  <link name="base_link">
    <inertial>
      <origin rpy="0 0 0" xyz="0.001637 0.0002 0.259547"/>
      <mass value="15.028392"/>
      <inertia ixx="0.376284" ixy="-8.8e-05" ixz="0.008378" iyy="0.342655" iyz="6.7e-05" izz="0.100648"/>
    </inertial>
    <visual>
      <origin rpy="0 0 0" xyz="0 0 0"/>
      <geometry>
        <mesh filename="../meshes_digit/torso.obj"/>
      </geometry>
    </visual>
    <collision>
      <origin rpy="0 0 0" xyz="0 0 0"/>
      <geometry>
        <mesh filename="../meshes_digit/torso.obj"/>
      </geometry>
    </collision>
  </link>
  <link name="left_hip_roll">
    <inertial>
      <origin rpy="0 0 0" xyz="-0.001967 0.000244 0.031435"/>
      <mass value="0.915088"/>
      <inertia ixx="0.001017" ixy="-3e-06" ixz="1.3e-05" iyy="0.001148" iyz="-4e-06" izz="0.000766"/>
    </inertial>
    <visual>
      <origin rpy="0 0 0" xyz="0 0 0"/>
      <geometry>
        <mesh filename="../meshes_digit/hip-yaw-housing.obj"/>
      </geometry>
    </visual>
    <collision>
      <origin rpy="0 0 0" xyz="0 0 0"/>
      <geometry>
        <mesh filename="../meshes_digit/hip-yaw-housing.obj"/>
      </geometry>
    </collision>
  </link>
  <link name="left_hip_yaw">
    <inertial>
      <origin rpy="0 0 0" xyz="1e-05 -0.001945 0.042033"/>
      <mass value="0.818753"/>
      <inertia ixx="0.001627" ixy="-1e-06" ixz="2e-06" iyy="0.001929" iyz="5.3e-05" izz="0.00077"/>
    </inertial>
    <visual>
      <origin rpy="0 0 0" xyz="0 0 0"/>
      <geometry>
        <mesh filename="../meshes_digit/hip-pitch-housing.obj"/>
      </geometry>
    </visual>
    <collision>
      <origin rpy="0 0 0" xyz="0 0 0"/>
      <geometry>
        <mesh filename="../meshes_digit/hip-pitch-housing.obj"/>
      </geometry>
    </collision>
  </link>
  <link name="left_hip_pitch">
    <inertial>
      <origin rpy="0 0 0" xyz="0.060537 0.000521 -0.038857"/>
      <mass value="6.244279"/>
      <inertia ixx="0.011533" ixy="-0.000171" ixz="0.000148" iyy="0.033345" iyz="0.000178" izz="0.033958"/>
    </inertial>
    <visual>
      <origin rpy="0 0 0" xyz="0 0 0"/>
      <geometry>
        <mesh filename="../meshes_digit/hip-pitch.obj"/>
      </geometry>
    </visual>
    <collision>
      <origin rpy="0 0 0" xyz="0 0 0"/>
      <geometry>
        <mesh filename="../meshes_digit/hip-pitch.obj"/>
      </geometry>
    </collision>
  </link>
  <link name="left_knee">
    <inertial>
      <origin rpy="0 0 0" xyz="0.045641 0.042154 0.001657"/>
      <mass value="1.227077"/>
      <inertia ixx="0.002643" ixy="-0.001832" ixz="6.6e-05" iyy="0.005098" iyz="4.5e-05" izz="0.007019"/>
    </inertial>
    <visual>
      <origin rpy="0 0 0" xyz="0 0 0"/>
      <geometry>
        <mesh filename="../meshes_digit/knee.obj"/>
      </geometry>
    </visual>
    <collision>
      <origin rpy="0 0 0" xyz="0 0 0"/>
      <geometry>
        <mesh filename="../meshes_digit/knee.obj"/>
      </geometry>
    </collision>
  </link>
  <link name="left_shin">
    <inertial>
      <origin rpy="0 0 0" xyz="0.174265 0.010265 0.00107"/>
      <mass value="0.895793"/>
      <inertia ixx="0.001128" ixy="0.001098" ixz="0.000196" iyy="0.022492" iyz="-3e-06" izz="0.022793"/>
    </inertial>
    <visual>
      <origin rpy="0 0 0" xyz="0 0 0"/>
      <geometry>
        <mesh filename="../meshes_digit/shin.obj"/>
      </geometry>
    </visual>
    <collision>
      <origin rpy="0 0 0" xyz="0 0 0"/>
      <geometry>
        <mesh filename="../meshes_digit/shin.obj"/>
      </geometry>
    </collision>
  </link>
  <link name="left_tarsus">
    <inertial>
      <origin rpy="0 0 0" xyz="0.000932 -0.029183 0.000678"/>
      <mass value="1.322865"/>
      <inertia ixx="0.000932" ixy="0.00061" ixz="0.000102" iyy="0.016409" iyz="9e-06" izz="0.016501"/>
    </inertial>
    <visual>
      <origin rpy="0 0 0" xyz="0 0 0"/>
      <geometry>
        <mesh filename="../meshes_digit/tarsus.obj"/>
      </geometry>
    </visual>
    <collision>
      <origin rpy="0 0 0" xyz="0 0 0"/>
      <geometry>
        <mesh filename="../meshes_digit/tarsus.obj"/>
      </geometry>
    </collision>
  </link>
  <link name="left_toe_pitch">
    <inertial>
      <origin rpy="0 0 0" xyz="-0.000141 2e-06 3e-06"/>
      <mass value="0.043881"/>
      <inertia ixx="5e-06" ixy="0" ixz="0" iyy="8e-06" iyz="0" izz="5e-06"/>
    </inertial>
    <visual>
      <origin rpy="0 0 0" xyz="0 0 0"/>
      <geometry>
        <mesh filename="../meshes_digit/toe-pitch.obj"/>
      </geometry>
    </visual>
    <collision>
      <origin rpy="0 0 0" xyz="0 0 0"/>
      <geometry>
        <mesh filename="../meshes_digit/toe-pitch.obj"/>
      </geometry>
    </collision>
  </link>
  <link name="left_toe_roll">
    <inertial>
      <origin rpy="0 0 0" xyz="9e-06 -0.028084 -0.023204"/>
      <mass value="0.531283"/>
      <inertia ixx="0.00187" ixy="0" ixz="0" iyy="0.001616" iyz="0.000566" izz="0.000843"/>
    </inertial>
    <visual>
      <origin rpy="0 0 0" xyz="0 0 0"/>
      <geometry>
        <mesh filename="../meshes_digit/toe-roll.obj"/>
      </geometry>
    </visual>
    <collision>
      <origin rpy="0 0 0" xyz="0 0 0"/>
      <geometry>
        <mesh filename="../meshes_digit/toe-roll.obj"/>
      </geometry>
    </collision>
  </link>
  <link name="left_foot">
    <visual>
      <origin rpy="0 0 0" xyz="0 0 0"/>
      <geometry>
        <sphere radius="0.01"/>
      </geometry>
    </visual>
  </link>
  <joint name="hip_abduction_left" type="revolute">
    <origin rpy="1.57079632679 -1.1955506 -1.57079632679" xyz="-0.001 0.091 0"/>
    <axis xyz="0 0 1"/>
    <parent link="base_link"/>
    <child link="left_hip_roll"/>
    <limit effort="150" lower="-1.0472" upper="1.0472" velocity="12.15"/>
    <dynamics damping="1.0" friction="1.0"/>
  </joint>
  <joint name="hip_rotation_left" type="revolute">
    <origin rpy="0 -1.57079632679 0" xyz="-0.0505 0 0.044"/>
    <axis xyz="0 0 1"/>
    <parent link="left_hip_roll"/>
    <child link="left_hip_yaw"/>
    <limit effort="150" lower="-0.698132" upper="0.698132" velocity="12.15"/>
    <dynamics damping="1.0" friction="1.0"/>
  </joint>
  <joint name="hip_flexion_left" type="revolute">
    <origin rpy="-1.57079632679 -0.785398163397 3.14159265359" xyz="0 0.004 0.068"/>
    <axis xyz="0 0 -1"/>
    <parent link="left_hip_yaw"/>
    <child link="left_hip_pitch"/>
    <limit effort="300" lower="-1.0472" upper="1.57079632679" velocity="8.5"/>
    <dynamics damping="1.0" friction="0.5"/>
  </joint>
  <joint name="knee_joint_left" type="revolute">
    <origin rpy="0 0 -1.57079632679" xyz="0.12 0 0.0045"/>
    <axis xyz="0 0 1"/>
    <parent link="left_hip_pitch"/>
    <child link="left_knee"/>
    <limit effort="300" lower="-1.2392" upper="0.8727" velocity="8.5085"/>
    <dynamics damping="1.0" friction="0.5"/>
  </joint>
  <joint name="knee_to_shin_left" type="fixed">
    <origin rpy="0 0 0" xyz="0.060677 0.047406 0"/>
    <parent link="left_knee"/>
    <child link="left_shin"/>
    <limit effort="0" lower="-0.35" upper="0.35" velocity="10"/>
<!--    <dynamics damping="1.0" friction="0.5"/>-->
  </joint>
  <joint name="shin_to_tarsus_left" type="revolute">
    <origin rpy="0 0 1.7976891" xyz="0.434759 0.02 0"/>
    <axis xyz="0 0 1"/>
    <parent link="left_shin"/>
    <child link="left_tarsus"/>
    <limit effort="300" lower="-0.8779" upper="1.0121" velocity="20"/>
    <dynamics damping="1.0" friction="0.5"/>
  </joint>
  <joint name="toe_pitch_joint_left" type="revolute">
    <origin rpy="0 0 1.1956" xyz="0.408 -0.04 0"/>
    <axis xyz="0 0 1"/>
    <parent link="left_tarsus"/>
    <child link="left_toe_pitch"/>
    <limit effort="100" lower="-0.785398163397" upper="0.785398163397" velocity="11.5"/>
    <dynamics damping="1.0" friction="1.0"/>
  </joint>
  <joint name="toe_roll_joint_left" type="revolute">
    <origin rpy="0 1.57079632679 0" xyz="0 0 0"/>
    <axis xyz="0 0 1"/>
    <parent link="left_toe_pitch"/>
    <child link="left_toe_roll"/>
    <limit effort="100" lower="-0.6109" upper="0.6109" velocity="11.5"/>
<!--    <limit effort="20" lower="-0.1" upper="0.1" velocity="11.5"/>-->
    <dynamics damping="1.0" friction="1.0"/>
  </joint>
  <joint name="foot_left" type="fixed">
    <origin rpy="-1.0471975512 0 -1.57079632679" xyz="0 -0.05456 -0.0315"/>
    <parent link="left_toe_roll"/>
    <child link="left_foot"/>
  </joint>
</robot>
